<?xml version="1.0" ?>
<!-- =================================================================================== -->
<!-- |    This document was autogenerated by xacro from /home/maretsu/ws_cogniman/install/cogniman_scene_description/share/cogniman_scene_description/urdf/cogniman_description.xacro | -->
<!-- |    EDITING THIS FILE BY HAND IS NOT RECOMMENDED                                 | -->
<!-- =================================================================================== -->
<robot name="cogniman_robot">
  <!-- ===FROM MOTOMAN=== -->
  <!-- ===FROM MOTOMAN=== -->
  <link name="screw_gripper">
    <visual>
      <geometry>
        <mesh filename="package://screw_gripper_description/mesh/visual/screw_gripper.stl"/>
      </geometry>
      <material name="">
        <color rgba="0.5686274509803921 0.5686274509803921 0.5686274509803921 1.0"/>
      </material>
    </visual>
    <collision>
      <geometry>
        <mesh filename="package://screw_gripper_description/mesh/collision/screw_gripper_collision.stl"/>
      </geometry>
    </collision>
  </link>
  <link name="tcp_screw_gripper"/>
  <joint name="screw_gripper_to_tcp" type="fixed">
    <origin rpy="0 0 0" xyz="0 0 0.2"/>
    <parent link="screw_gripper"/>
    <child link="tcp_screw_gripper"/>
  </joint>
  <!-- ===FROM MOTOMAN=== -->
  <!-- ===FROM MOTOMAN=== -->
  <link name="equerre_1">
    <visual>
      <geometry>
        <mesh filename="package://positionning_tool/mesh/visual/equerre.stl"/>
      </geometry>
      <material name="">
        <color rgba="0.7686274509803922 0.0 0.027450980392156862 1.0"/>
      </material>
    </visual>
    <collision>
      <geometry>
        <mesh filename="package://positionning_tool/mesh/collision/equerre_collision.stl"/>
      </geometry>
    </collision>
  </link>
  <!-- ===FROM MOTOMAN=== -->
  <!-- ===FROM MOTOMAN=== -->
  <link name="equerre_2">
    <visual>
      <geometry>
        <mesh filename="package://positionning_tool/mesh/visual/equerre.stl"/>
      </geometry>
      <material name="">
        <color rgba="0.7686274509803922 0.0 0.027450980392156862 1.0"/>
      </material>
    </visual>
    <collision>
      <geometry>
        <mesh filename="package://positionning_tool/mesh/collision/equerre_collision.stl"/>
      </geometry>
    </collision>
  </link>
  <!-- ===FROM MOTOMAN=== -->
  <!-- ===FROM MOTOMAN=== -->
  <link name="equerre_3">
    <visual>
      <geometry>
        <mesh filename="package://positionning_tool/mesh/visual/equerre.stl"/>
      </geometry>
      <material name="">
        <color rgba="0.7686274509803922 0.0 0.027450980392156862 1.0"/>
      </material>
    </visual>
    <collision>
      <geometry>
        <mesh filename="package://positionning_tool/mesh/collision/equerre_collision.stl"/>
      </geometry>
    </collision>
  </link>
  <!-- ===FROM MOTOMAN=== -->
  <!-- ===FROM MOTOMAN=== -->
  <link name="clamp_1">
    <visual>
      <geometry>
        <mesh filename="package://toggle_clamp/mesh/visual/clamp.stl"/>
      </geometry>
      <material name="">
        <color rgba="0.5686274509803921 0.5686274509803921 0.5686274509803921 1.0"/>
      </material>
    </visual>
    <collision>
      <geometry>
        <mesh filename="package://toggle_clamp/mesh/collision/clamp_collision.stl"/>
      </geometry>
    </collision>
  </link>
  <!-- ===FROM MOTOMAN=== -->
  <!-- ===FROM MOTOMAN=== -->
  <link name="clamp_2">
    <visual>
      <geometry>
        <mesh filename="package://toggle_clamp/mesh/visual/clamp.stl"/>
      </geometry>
      <material name="">
        <color rgba="0.5686274509803921 0.5686274509803921 0.5686274509803921 1.0"/>
      </material>
    </visual>
    <collision>
      <geometry>
        <mesh filename="package://toggle_clamp/mesh/collision/clamp_collision.stl"/>
      </geometry>
    </collision>
  </link>
  <!-- ===FROM MOTOMAN=== -->
  <!-- ===FROM MOTOMAN=== -->
  <link name="plateforme">
    <visual>
      <geometry>
        <mesh filename="package://plateforme_description/mesh/visual/plateform.stl"/>
      </geometry>
      <material name="">
        <color rgba="1.0 1.0 1.0 1.0"/>
      </material>
    </visual>
    <collision>
      <geometry>
        <mesh filename="package://plateforme_description/mesh/collision/plateform_collision.stl"/>
      </geometry>
    </collision>
  </link>
  <!-- link list -->
  <link name="base_link">
    <visual>
      <geometry>
        <mesh filename="package://motoman_gp7_support/meshes/visual/gp7_base_link.stl"/>
      </geometry>
      <material name="">
        <color rgba="0.12941176470588237 0.14901960784313725 0.7490196078431373 1.0"/>
      </material>
    </visual>
    <collision>
      <geometry>
        <mesh filename="package://motoman_gp7_support/meshes/collision/gp7_base_link.stl"/>
      </geometry>
    </collision>
  </link>
  <link name="link_1_s">
    <visual>
      <geometry>
        <mesh filename="package://motoman_gp7_support/meshes/visual/gp7_link_1_s.stl"/>
      </geometry>
      <material name="">
        <color rgba="0.12941176470588237 0.14901960784313725 0.7490196078431373 1.0"/>
      </material>
    </visual>
    <collision>
      <geometry>
        <mesh filename="package://motoman_gp7_support/meshes/collision/gp7_link_1_s.stl"/>
      </geometry>
    </collision>
  </link>
  <link name="link_2_l">
    <visual>
      <geometry>
        <mesh filename="package://motoman_gp7_support/meshes/visual/gp7_link_2_l.stl"/>
      </geometry>
      <material name="">
        <color rgba="0.12941176470588237 0.14901960784313725 0.7490196078431373 1.0"/>
      </material>
    </visual>
    <collision>
      <geometry>
        <mesh filename="package://motoman_gp7_support/meshes/collision/gp7_link_2_l.stl"/>
      </geometry>
    </collision>
  </link>
  <link name="link_3_u">
    <visual>
      <geometry>
        <mesh filename="package://motoman_gp7_support/meshes/visual/gp7_link_3_u.stl"/>
      </geometry>
      <material name="">
        <color rgba="0.12941176470588237 0.14901960784313725 0.7490196078431373 1.0"/>
      </material>
    </visual>
    <collision>
      <geometry>
        <mesh filename="package://motoman_gp7_support/meshes/collision/gp7_link_3_u.stl"/>
      </geometry>
    </collision>
  </link>
  <link name="link_4_r">
    <visual>
      <geometry>
        <mesh filename="package://motoman_gp7_support/meshes/visual/gp7_link_4_r.stl"/>
      </geometry>
      <material name="">
        <color rgba="0.12941176470588237 0.14901960784313725 0.7490196078431373 1.0"/>
      </material>
    </visual>
    <collision>
      <geometry>
        <mesh filename="package://motoman_gp7_support/meshes/collision/gp7_link_4_r.stl"/>
      </geometry>
    </collision>
  </link>
  <link name="link_5_b">
    <visual>
      <geometry>
        <mesh filename="package://motoman_gp7_support/meshes/visual/gp7_link_5_b.stl"/>
      </geometry>
      <material name="">
        <color rgba="0.12941176470588237 0.14901960784313725 0.7490196078431373 1.0"/>
      </material>
    </visual>
    <collision>
      <geometry>
        <mesh filename="package://motoman_gp7_support/meshes/collision/gp7_link_5_b.stl"/>
      </geometry>
    </collision>
  </link>
  <link name="link_6_t">
    <visual>
      <geometry>
        <mesh filename="package://motoman_gp7_support/meshes/visual/gp7_link_6_t.stl"/>
      </geometry>
      <material name="">
        <color rgba="0.12941176470588237 0.14901960784313725 0.7490196078431373 1.0"/>
      </material>
    </visual>
    <collision>
      <geometry>
        <mesh filename="package://motoman_gp7_support/meshes/collision/gp7_link_6_t.stl"/>
      </geometry>
    </collision>
  </link>
  <link name="tool0"/>
  <!-- end of link list -->
  <!-- joint list -->
  <joint name="joint_1_s" type="revolute">
    <parent link="base_link"/>
    <child link="link_1_s"/>
    <origin rpy="0 0 0" xyz="0 0 0.330"/>
    <axis xyz="0 0 1"/>
    <limit effort="212.66" lower="-2.9670" upper="2.9670" velocity="6.5448"/>
  </joint>
  <joint name="joint_2_l" type="revolute">
    <parent link="link_1_s"/>
    <child link="link_2_l"/>
    <origin rpy="0 0 0" xyz="0.040 0 0"/>
    <axis xyz="0 1 0"/>
    <limit effort="205.80" lower="-1.1344" upper="2.5307" velocity="5.4977"/>
  </joint>
  <joint name="joint_3_u" type="revolute">
    <parent link="link_2_l"/>
    <child link="link_3_u"/>
    <origin rpy="0 0 0" xyz="0 0 0.445"/>
    <axis xyz="0 -1 0"/>
    <limit effort="106.82" lower="-1.2217" upper="3.3161" velocity="7.1558"/>
  </joint>
  <joint name="joint_4_r" type="revolute">
    <parent link="link_3_u"/>
    <child link="link_4_r"/>
    <origin rpy="0 0 0" xyz="0.440 0 0.040"/>
    <axis xyz="-1 0 0"/>
    <limit effort="55.86" lower="-3.3161" upper="3.3161" velocity="9.5993"/>
  </joint>
  <joint name="joint_5_b" type="revolute">
    <parent link="link_4_r"/>
    <child link="link_5_b"/>
    <origin rpy="0 0 0" xyz="0 0 0"/>
    <axis xyz="0 -1 0"/>
    <limit effort="32.68" lower="-2.3561" upper="2.3561" velocity="9.5993"/>
  </joint>
  <joint name="joint_6_t" type="revolute">
    <parent link="link_5_b"/>
    <child link="link_6_t"/>
    <origin rpy="0 0 0" xyz="0 0 0"/>
    <axis xyz="-1 0 0"/>
    <limit effort="22.54" lower="-6.2944" upper="6.2944" velocity="17.4845"/>
  </joint>
  <joint name="joint_6_t-tool0" type="fixed">
    <origin rpy="3.1415926 -1.570796 0" xyz="0.080 0 0"/>
    <parent link="link_6_t"/>
    <child link="tool0"/>
  </joint>
  <!-- end of joint list -->
  <!-- ROS base_link to Robot Manufacturer World Coordinates transform -->
  <link name="base"/>
  <joint name="base_link-base" type="fixed">
    <origin rpy="0 0 0" xyz="0 0 0.330"/>
    <parent link="base_link"/>
    <child link="base"/>
  </joint>
  <!-- link list -->
  <link name="base_link">
    <visual>
      <geometry>
        <mesh filename="package://motoman_gp7_support/meshes/visual/gp7_base_link.stl"/>
      </geometry>
      <material name="">
        <color rgba="0.12941176470588237 0.14901960784313725 0.7490196078431373 1.0"/>
      </material>
    </visual>
    <collision>
      <geometry>
        <mesh filename="package://motoman_gp7_support/meshes/collision/gp7_base_link.stl"/>
      </geometry>
    </collision>
  </link>
  <link name="link_1_s">
    <visual>
      <geometry>
        <mesh filename="package://motoman_gp7_support/meshes/visual/gp7_link_1_s.stl"/>
      </geometry>
      <material name="">
        <color rgba="0.12941176470588237 0.14901960784313725 0.7490196078431373 1.0"/>
      </material>
    </visual>
    <collision>
      <geometry>
        <mesh filename="package://motoman_gp7_support/meshes/collision/gp7_link_1_s.stl"/>
      </geometry>
    </collision>
  </link>
  <link name="link_2_l">
    <visual>
      <geometry>
        <mesh filename="package://motoman_gp7_support/meshes/visual/gp7_link_2_l.stl"/>
      </geometry>
      <material name="">
        <color rgba="0.12941176470588237 0.14901960784313725 0.7490196078431373 1.0"/>
      </material>
    </visual>
    <collision>
      <geometry>
        <mesh filename="package://motoman_gp7_support/meshes/collision/gp7_link_2_l.stl"/>
      </geometry>
    </collision>
  </link>
  <link name="link_3_u">
    <visual>
      <geometry>
        <mesh filename="package://motoman_gp7_support/meshes/visual/gp7_link_3_u.stl"/>
      </geometry>
      <material name="">
        <color rgba="0.12941176470588237 0.14901960784313725 0.7490196078431373 1.0"/>
      </material>
    </visual>
    <collision>
      <geometry>
        <mesh filename="package://motoman_gp7_support/meshes/collision/gp7_link_3_u.stl"/>
      </geometry>
    </collision>
  </link>
  <link name="link_4_r">
    <visual>
      <geometry>
        <mesh filename="package://motoman_gp7_support/meshes/visual/gp7_link_4_r.stl"/>
      </geometry>
      <material name="">
        <color rgba="0.12941176470588237 0.14901960784313725 0.7490196078431373 1.0"/>
      </material>
    </visual>
    <collision>
      <geometry>
        <mesh filename="package://motoman_gp7_support/meshes/collision/gp7_link_4_r.stl"/>
      </geometry>
    </collision>
  </link>
  <link name="link_5_b">
    <visual>
      <geometry>
        <mesh filename="package://motoman_gp7_support/meshes/visual/gp7_link_5_b.stl"/>
      </geometry>
      <material name="">
        <color rgba="0.12941176470588237 0.14901960784313725 0.7490196078431373 1.0"/>
      </material>
    </visual>
    <collision>
      <geometry>
        <mesh filename="package://motoman_gp7_support/meshes/collision/gp7_link_5_b.stl"/>
      </geometry>
    </collision>
  </link>
  <link name="link_6_t">
    <visual>
      <geometry>
        <mesh filename="package://motoman_gp7_support/meshes/visual/gp7_link_6_t.stl"/>
      </geometry>
      <material name="">
        <color rgba="0.12941176470588237 0.14901960784313725 0.7490196078431373 1.0"/>
      </material>
    </visual>
    <collision>
      <geometry>
        <mesh filename="package://motoman_gp7_support/meshes/collision/gp7_link_6_t.stl"/>
      </geometry>
    </collision>
  </link>
  <link name="tool0"/>
  <!-- end of link list -->
  <!-- joint list -->
  <joint name="joint_1_s" type="revolute">
    <parent link="base_link"/>
    <child link="link_1_s"/>
    <origin rpy="0 0 0" xyz="0 0 0.330"/>
    <axis xyz="0 0 1"/>
    <limit effort="212.66" lower="-2.9670" upper="2.9670" velocity="6.5448"/>
  </joint>
  <joint name="joint_2_l" type="revolute">
    <parent link="link_1_s"/>
    <child link="link_2_l"/>
    <origin rpy="0 0 0" xyz="0.040 0 0"/>
    <axis xyz="0 1 0"/>
    <limit effort="205.80" lower="-1.1344" upper="2.5307" velocity="5.4977"/>
  </joint>
  <joint name="joint_3_u" type="revolute">
    <parent link="link_2_l"/>
    <child link="link_3_u"/>
    <origin rpy="0 0 0" xyz="0 0 0.445"/>
    <axis xyz="0 -1 0"/>
    <limit effort="106.82" lower="-1.2217" upper="3.3161" velocity="7.1558"/>
  </joint>
  <joint name="joint_4_r" type="revolute">
    <parent link="link_3_u"/>
    <child link="link_4_r"/>
    <origin rpy="0 0 0" xyz="0.440 0 0.040"/>
    <axis xyz="-1 0 0"/>
    <limit effort="55.86" lower="-3.3161" upper="3.3161" velocity="9.5993"/>
  </joint>
  <joint name="joint_5_b" type="revolute">
    <parent link="link_4_r"/>
    <child link="link_5_b"/>
    <origin rpy="0 0 0" xyz="0 0 0"/>
    <axis xyz="0 -1 0"/>
    <limit effort="32.68" lower="-2.3561" upper="2.3561" velocity="9.5993"/>
  </joint>
  <joint name="joint_6_t" type="revolute">
    <parent link="link_5_b"/>
    <child link="link_6_t"/>
    <origin rpy="0 0 0" xyz="0 0 0"/>
    <axis xyz="-1 0 0"/>
    <limit effort="22.54" lower="-6.2944" upper="6.2944" velocity="17.4845"/>
  </joint>
  <joint name="joint_6_t-tool0" type="fixed">
    <origin rpy="3.1415926 -1.570796 0" xyz="0.080 0 0"/>
    <parent link="link_6_t"/>
    <child link="tool0"/>
  </joint>
  <!-- end of joint list -->
  <!-- ROS base_link to Robot Manufacturer World Coordinates transform -->
  <link name="base"/>
  <joint name="base_link-base" type="fixed">
    <origin rpy="0 0 0" xyz="0 0 0.330"/>
    <parent link="base_link"/>
    <child link="base"/>
  </joint>
  <!-- Ajouter les inerties à chaque lien avec le préfixe -->
  <link name="base_link">
    <inertial>
      <inertia ixx="0.03305" ixy="0" ixz="0" iyy="0.03305" iyz="0" izz="0.0361"/>
      <mass value="8"/>
    </inertial>
  </link>
  <link name="link_1_s">
    <inertial>
      <inertia ixx="0.46666666666666673" ixy="0" ixz="0" iyy="0.46666666666666673" iyz="0" izz="0.1"/>
      <mass value="5"/>
    </inertial>
  </link>
  <link name="link_2_l">
    <inertial>
      <inertia ixx="0.053333333333333344" ixy="0" ixz="0" iyy="0.6933333333333334" iyz="0" izz="0.6933333333333334"/>
      <mass value="8"/>
    </inertial>
  </link>
  <link name="link_3_u">
    <inertial>
      <inertia ixx="0.23583333333333337" ixy="0" ixz="0" iyy="0.23583333333333337" iyz="0" izz="0.045"/>
      <mass value="4"/>
    </inertial>
  </link>
  <link name="link_4_r">
    <inertial>
      <inertia ixx="0.012000000000000002" ixy="0" ixz="0" iyy="0.012000000000000002" iyz="0" izz="0.012000000000000002"/>
      <mass value="0.3"/>
    </inertial>
  </link>
  <link name="link_5_b">
    <inertial>
      <inertia ixx="0.02833333333333334" ixy="0" ixz="0" iyy="0.02833333333333334" iyz="0" izz="0.053333333333333344"/>
      <mass value="2"/>
    </inertial>
  </link>
  <link name="link_6_t">
    <inertial>
      <inertia ixx="0.021458333333333333" ixy="0" ixz="0" iyy="0.021458333333333333" iyz="0" izz="0.0012500000000000002"/>
      <mass value="1"/>
    </inertial>
  </link>
  <link name="tool0">
    <inertial>
      <inertia ixx="0.001666666666666667" ixy="0" ixz="0" iyy="0.001666666666666667" iyz="0" izz="0.001666666666666667"/>
      <mass value="1"/>
    </inertial>
  </link>
  <link name="world"/>
  <joint name="world_to_robot" type="fixed">
    <origin rpy="0 0 0" xyz="0 0 0.24"/>
    <parent link="world"/>
    <child link="base_link"/>
  </joint>
  <joint name="robot_to_plateforme" type="fixed">
    <origin rpy="0 0 3.14" xyz="0 0 0"/>
    <parent link="base_link"/>
    <child link="plateforme"/>
  </joint>
  <!-- ======  TOOL ====== -->
  <joint name="tool0_to_screw_gripper" type="fixed">
    <origin rpy="0 0 0" xyz="0 0 0"/>
    <parent link="tool0"/>
    <child link="screw_gripper"/>
  </joint>
  <!-- ======  CLAMP ====== -->
  <joint name="robot_to_clamp1" type="fixed">
    <origin rpy="0 0 0" xyz="0.5 0.5 0"/>
    <parent link="base_link"/>
    <child link="clamp_1"/>
  </joint>
  <joint name="robot_to_clamp2" type="fixed">
    <origin rpy="0 0 0" xyz="0.2 0.2 0"/>
    <parent link="base_link"/>
    <child link="clamp_2"/>
  </joint>
  <!-- ======  EQUERRE ====== -->
  <joint name="robot_to_equerre1" type="fixed">
    <origin rpy="0 0 0" xyz="1 1 0"/>
    <parent link="base_link"/>
    <child link="equerre_1"/>
  </joint>
  <joint name="robot_to_equerre2" type="fixed">
    <origin rpy="0 0 0" xyz="1 1.2 0"/>
    <parent link="base_link"/>
    <child link="equerre_2"/>
  </joint>
  <joint name="robot_to_equerre3" type="fixed">
    <origin rpy="0 0 0" xyz="1 1.5 0"/>
    <parent link="base_link"/>
    <child link="equerre_3"/>
  </joint>
</robot>
