<?xml version="1.0" ?>
<!-- =================================================================================== -->
<!-- |    This document was autogenerated by xacro from /home/srobert/ws_cogniman/install/cogniman_scene_description/share/cogniman_scene_description/urdf/cogniman_description.xacro | -->
<!-- |    EDITING THIS FILE BY HAND IS NOT RECOMMENDED                                 | -->
<!-- =================================================================================== -->
<robot name="cogniman_robot">
  <link name="clamp_1">
    <visual>
      <geometry>
        <mesh filename="package://toggle_clamp/mesh/visual/clamp.stl"/>
      </geometry>
    </visual>
    <collision>
      <geometry>
        <mesh filename="package://toggle_clamp/mesh/collision/clamp_collision.stl"/>
      </geometry>
    </collision>
  </link>
  <link name="clamp_2">
    <visual>
      <geometry>
        <mesh filename="package://toggle_clamp/mesh/visual/clamp.stl"/>
      </geometry>
    </visual>
    <collision>
      <geometry>
        <mesh filename="package://toggle_clamp/mesh/collision/clamp_collision.stl"/>
      </geometry>
    </collision>
  </link>
  <link name="plateforme">
    <visual>
      <geometry>
        <mesh filename="package://plateforme_description/mesh/visual/plateform.stl"/>
      </geometry>
    </visual>
    <collision>
      <geometry>
        <mesh filename="package://plateforme_description/mesh/collision/plateform_collision.stl"/>
      </geometry>
    </collision>
  </link>
  <!-- link list -->
  <link name="base_link">
    <visual>
      <geometry>
        <mesh filename="file:////home/srobert/ws_cogniman/install/motoman_gp7_support/share/motoman_gp7_support/meshes/visual/gp7_base_link.stl"/>
      </geometry>
      <material name="">
        <color rgba="0.12941176470588237 0.14901960784313725 0.7490196078431373 1.0"/>
      </material>
    </visual>
    <collision>
      <geometry>
        <mesh filename="file:////home/srobert/ws_cogniman/install/motoman_gp7_support/share/motoman_gp7_support/meshes/collision/gp7_base_link.stl"/>
      </geometry>
    </collision>
    <inertial>
      <inertia ixx="0.03305" ixy="0" ixz="0" iyy="0.03305" iyz="0" izz="0.0361"/>
      <mass value="0.008"/>
    </inertial>
  </link>
  <gazebo reference="base_link">
    <material>Gazebo/Blue</material>
  </gazebo>
  <link name="link_1_s">
    <visual>
      <geometry>
        <mesh filename="file:////home/srobert/ws_cogniman/install/motoman_gp7_support/share/motoman_gp7_support/meshes/visual/gp7_link_1_s.stl"/>
      </geometry>
      <material name="">
        <color rgba="0.12941176470588237 0.14901960784313725 0.7490196078431373 1.0"/>
      </material>
    </visual>
    <collision>
      <geometry>
        <mesh filename="file:////home/srobert/ws_cogniman/install/motoman_gp7_support/share/motoman_gp7_support/meshes/collision/gp7_link_1_s.stl"/>
      </geometry>
    </collision>
    <inertial>
      <inertia ixx="0.02478125" ixy="0" ixz="0" iyy="0.02478125" iyz="0" izz="0.0225625"/>
      <mass value="0.005"/>
    </inertial>
  </link>
  <gazebo reference="link_1_s">
    <material>Gazebo/Blue</material>
  </gazebo>
  <link name="link_2_l">
    <visual>
      <geometry>
        <mesh filename="file:////home/srobert/ws_cogniman/install/motoman_gp7_support/share/motoman_gp7_support/meshes/visual/gp7_link_2_l.stl"/>
      </geometry>
      <material name="">
        <color rgba="0.12941176470588237 0.14901960784313725 0.7490196078431373 1.0"/>
      </material>
    </visual>
    <collision>
      <origin rpy="1.5707963267948966 0.0 -1.5707963267948966" xyz="-0.03 -0.0 -0.33"/>
      <geometry>
        <mesh filename="file:////home/srobert/ws_cogniman/install/motoman_gp7_support/share/motoman_gp7_support/meshes/collision/gp7_link_2_l.stl" scale="0.001 0.001 0.001"/>
      </geometry>
    </collision>
    <inertial>
      <inertia ixx="0.07889583333333335" ixy="0" ixz="0" iyy="0.07889583333333335" iyz="0" izz="0.045125"/>
      <mass value="0.01"/>
    </inertial>
  </link>
  <gazebo reference="link_2_l">
    <material>Gazebo/Blue</material>
  </gazebo>
  <link name="link_3_u">
    <visual>
      <geometry>
        <mesh filename="file:////home/srobert/ws_cogniman/install/motoman_gp7_support/share/motoman_gp7_support/meshes/visual/gp7_link_3_u.stl"/>
      </geometry>
      <material name="">
        <color rgba="0.12941176470588237 0.14901960784313725 0.7490196078431373 1.0"/>
      </material>
    </visual>
    <collision>
      <geometry>
        <mesh filename="file:////home/srobert/ws_cogniman/install/motoman_gp7_support/share/motoman_gp7_support/meshes/collision/gp7_link_3_u.stl"/>
      </geometry>
    </collision>
    <inertial>
      <inertia ixx="0.012358333333333334" ixy="0" ixz="0" iyy="0.012358333333333334" iyz="0" izz="0.01805"/>
      <mass value="0.004"/>
    </inertial>
  </link>
  <gazebo reference="link_3_u">
    <material>Gazebo/Blue</material>
  </gazebo>
  <link name="link_4_r">
    <visual>
      <geometry>
        <mesh filename="file:////home/srobert/ws_cogniman/install/motoman_gp7_support/share/motoman_gp7_support/meshes/visual/gp7_link_4_r.stl"/>
      </geometry>
      <material name="">
        <color rgba="0.12941176470588237 0.14901960784313725 0.7490196078431373 1.0"/>
      </material>
    </visual>
    <collision>
      <geometry>
        <mesh filename="file:////home/srobert/ws_cogniman/install/motoman_gp7_support/share/motoman_gp7_support/meshes/collision/gp7_link_4_r.stl"/>
      </geometry>
    </collision>
    <inertial>
      <inertia ixx="0.031587500000000004" ixy="0" ixz="0" iyy="0.031587500000000004" iyz="0" izz="0.027075000000000002"/>
      <mass value="0.006"/>
    </inertial>
  </link>
  <gazebo reference="link_4_r">
    <material>Gazebo/Blue</material>
  </gazebo>
  <link name="link_5_b">
    <visual>
      <geometry>
        <mesh filename="file:////home/srobert/ws_cogniman/install/motoman_gp7_support/share/motoman_gp7_support/meshes/visual/gp7_link_5_b.stl"/>
      </geometry>
      <material name="">
        <color rgba="0.12941176470588237 0.14901960784313725 0.7490196078431373 1.0"/>
      </material>
    </visual>
    <collision>
      <geometry>
        <mesh filename="file:////home/srobert/ws_cogniman/install/motoman_gp7_support/share/motoman_gp7_support/meshes/collision/gp7_link_5_b.stl"/>
      </geometry>
    </collision>
    <inertial>
      <inertia ixx="0.009268750000000001" ixy="0" ixz="0" iyy="0.009268750000000001" iyz="0" izz="0.013537500000000001"/>
      <mass value="0.003"/>
    </inertial>
  </link>
  <gazebo reference="link_5_b">
    <material>Gazebo/Blue</material>
  </gazebo>
  <link name="link_6_t">
    <visual>
      <geometry>
        <mesh filename="file:////home/srobert/ws_cogniman/install/motoman_gp7_support/share/motoman_gp7_support/meshes/visual/gp7_link_6_t.stl"/>
      </geometry>
      <material name="">
        <color rgba="0.12941176470588237 0.14901960784313725 0.7490196078431373 1.0"/>
      </material>
    </visual>
    <collision>
      <geometry>
        <mesh filename="file:////home/srobert/ws_cogniman/install/motoman_gp7_support/share/motoman_gp7_support/meshes/collision/gp7_link_6_t.stl"/>
      </geometry>
    </collision>
    <inertial>
      <inertia ixx="0.0053765" ixy="0" ixz="0" iyy="0.0053765" iyz="0" izz="0.009025"/>
      <mass value="0.002"/>
    </inertial>
  </link>
  <gazebo reference="link_6_t">
    <material>Gazebo/Blue</material>
  </gazebo>
  <link name="tool0"/>
  <!-- end of link list -->
  <!-- joint list -->
  <joint name="joint_1_s" type="revolute">
    <parent link="base_link"/>
    <child link="link_1_s"/>
    <origin rpy="0 0 0" xyz="0 0 0.330"/>
    <axis xyz="0 0 1"/>
    <limit effort="212.66" lower="-1.9" upper="1.9" velocity="6.5448"/>
  </joint>
  <joint name="joint_2_l" type="revolute">
    <parent link="link_1_s"/>
    <child link="link_2_l"/>
    <origin rpy="0 0 0" xyz="0.040 0 0"/>
    <axis xyz="0 1 0"/>
    <limit effort="205.80" lower="-1.1" upper="1.47" velocity="5.4977"/>
  </joint>
  <joint name="joint_3_u" type="revolute">
    <parent link="link_2_l"/>
    <child link="link_3_u"/>
    <origin rpy="0 0 0" xyz="0 0 0.445"/>
    <axis xyz="0 -1 0"/>
    <limit effort="106.82" lower="-1.2" upper="3.2" velocity="7.1558"/>
  </joint>
  <joint name="joint_4_r" type="revolute">
    <parent link="link_3_u"/>
    <child link="link_4_r"/>
    <origin rpy="0 0 0" xyz="0.440 0 0.040"/>
    <axis xyz="-1 0 0"/>
    <limit effort="55.86" lower="-3.0" upper="3.0" velocity="9.5993"/>
  </joint>
  <joint name="joint_5_b" type="revolute">
    <parent link="link_4_r"/>
    <child link="link_5_b"/>
    <origin rpy="0 0 0" xyz="0 0 0"/>
    <axis xyz="0 -1 0"/>
    <limit effort="32.68" lower="-2.34" upper="2.34" velocity="9.5993"/>
  </joint>
  <joint name="joint_6_t" type="revolute">
    <parent link="link_5_b"/>
    <child link="link_6_t"/>
    <origin rpy="0 0 0" xyz="0 0 0"/>
    <axis xyz="-1 0 0"/>
    <limit effort="22.54" lower="-6.2" upper="6.2" velocity="17.4845"/>
  </joint>
  <joint name="joint_6_t-tool0" type="fixed">
    <origin rpy="3.1415926 -1.570796 0" xyz="0.080 0 0"/>
    <parent link="link_6_t"/>
    <child link="tool0"/>
  </joint>
  <!-- end of joint list -->
  <!-- ROS base_link to Robot Manufacturer World Coordinates transform -->
  <!-- <link name="${prefix}base" />
    <joint name="${prefix}base_link-base" type="fixed">
        <origin xyz="0 0 0.330" rpy="0 0 0"/>
        <parent link="${prefix}base_link"/>
        <child link="${prefix}base"/>
    </joint> -->
  <link name="world"/>
  <joint name="world_to_plateforme" type="fixed">
    <origin rpy="0 0 0" xyz="1 0 0"/>
    <parent link="world"/>
    <child link="plateforme"/>
  </joint>
  <joint name="plateforme_to_robot" type="fixed">
    <origin rpy="0 0 0" xyz="1 0 0"/>
    <parent link="plateforme"/>
    <child link="base_link"/>
  </joint>
  <joint name="robot_to_clamp1" type="fixed">
    <origin rpy="0 0 0" xyz="0 0 0"/>
    <parent link="base_link"/>
    <child link="clamp_1"/>
  </joint>
  <joint name="robot_to_clamp2" type="fixed">
    <origin rpy="0 0 0" xyz="0 0 0"/>
    <parent link="base_link"/>
    <child link="clamp_2"/>
  </joint>
</robot>
